<robot name="g1_29dof_rev_1_0">
  <material name="dark">
    <color rgba="0.2 0.2 0.2 1" />
  </material>
  <material name="white">
    <color rgba="0.7 0.7 0.7 1" />
  </material>

  <mujoco>
    <compiler meshdir="meshes" discardvisual="false" />
  </mujoco>

  
  

  <link name="pelvis">
    <inertial>
      <origin xyz="0 0 -0.07605" rpy="0 0 0" />
      <mass value="3.813" />
      <inertia ixx="0.010549" ixy="0" ixz="2.1E-06" iyy="0.0093089" iyz="0" izz="0.0079184" />
    </inertial>
    <visual>
      <origin xyz="0 0 0" rpy="0 0 0" />
      <geometry>
        <mesh filename="meshes/pelvis.STL" />
      </geometry>
      <material name="dark" />
    </visual>
  </link>
  <link name="pelvis_contour_link">
    <inertial>
      <origin xyz="0 0 0" rpy="0 0 0" />
      <mass value="0.001" />
      <inertia ixx="1e-7" ixy="0" ixz="0" iyy="1e-7" iyz="0" izz="1e-7" />
    </inertial>
    <visual>
      <origin xyz="0 0 0" rpy="0 0 0" />
      <geometry>
        <mesh filename="meshes/pelvis_contour_link.STL" />
      </geometry>
      <material name="white" />
    </visual>
    <collision>
      <origin xyz="0 0 0" rpy="0 0 0" />
      <geometry>
        <mesh filename="meshes/pelvis_contour_link.STL" />
      </geometry>
    </collision>
  </link>
  <joint name="pelvis_contour_joint" type="fixed">
    <parent link="pelvis" />
    <child link="pelvis_contour_link" />
  </joint>

  
  <link name="left_hip_pitch_link">
    <inertial>
      <origin xyz="0.002741 0.047791 -0.02606" rpy="0 0 0" />
      <mass value="1.35" />
      <inertia ixx="0.001811" ixy="3.68E-05" ixz="-3.44E-05" iyy="0.0014193" iyz="0.000171" izz="0.0012812" />
    </inertial>
    <visual>
      <origin xyz="0 0 0" rpy="0 0 0" />
      <geometry>
        <mesh filename="meshes/left_hip_pitch_link.STL" />
      </geometry>
      <material name="dark" />
    </visual>
    <collision>
      <origin xyz="0 0 0" rpy="0 0 0" />
      <geometry>
        <mesh filename="meshes/left_hip_pitch_link.STL" />
      </geometry>
    </collision>
  </link>
  <joint name="left_hip_pitch_joint" type="revolute">
    <origin xyz="0 0.064452 -0.1027" rpy="0 0 0" />
    <parent link="pelvis" />
    <child link="left_hip_pitch_link" />
    <axis xyz="0 1 0" />
    <limit lower="-2.5307" upper="2.8798" effort="88" velocity="32" />
  </joint>
  <link name="left_hip_roll_link">
    <inertial>
      <origin xyz="0.029812 -0.001045 -0.087934" rpy="0 0 0" />
      <mass value="1.52" />
      <inertia ixx="0.0023773" ixy="-3.8E-06" ixz="-0.0003908" iyy="0.0024123" iyz="1.84E-05" izz="0.0016595" />
    </inertial>
    <visual>
      <origin xyz="0 0 0" rpy="0 0 0" />
      <geometry>
        <mesh filename="meshes/left_hip_roll_link.STL" />
      </geometry>
      <material name="white" />
    </visual>
    <collision>
      <origin xyz="0 0 0" rpy="0 0 0" />
      <geometry>
        <mesh filename="meshes/left_hip_roll_link.STL" />
      </geometry>
    </collision>
  </link>
  <joint name="left_hip_roll_joint" type="revolute">
    <origin xyz="0 0.052 -0.030465" rpy="0 -0.1749 0" />
    <parent link="left_hip_pitch_link" />
    <child link="left_hip_roll_link" />
    <axis xyz="1 0 0" />
    <limit lower="-0.5236" upper="2.9671" effort="139" velocity="20" />
  </joint>
  <link name="left_hip_yaw_link">
    <inertial>
      <origin xyz="-0.057709 -0.010981 -0.15078" rpy="0 0 0" />
      <mass value="1.702" />
      <inertia ixx="0.0057774" ixy="-0.0005411" ixz="-0.0023948" iyy="0.0076124" iyz="-0.0007072" izz="0.003149" />
    </inertial>
    <visual>
      <origin xyz="0 0 0" rpy="0 0 0" />
      <geometry>
        <mesh filename="meshes/left_hip_yaw_link.STL" />
      </geometry>
      <material name="white" />
    </visual>
    <collision>
      <origin xyz="0 0 0" rpy="0 0 0" />
      <geometry>
        <mesh filename="meshes/left_hip_yaw_link.STL" />
      </geometry>
    </collision>
  </link>
  <joint name="left_hip_yaw_joint" type="revolute">
    <origin xyz="0.025001 0 -0.12412" rpy="0 0 0" />
    <parent link="left_hip_roll_link" />
    <child link="left_hip_yaw_link" />
    <axis xyz="0 0 1" />
    <limit lower="-2.7576" upper="2.7576" effort="88" velocity="32" />
  </joint>
  <link name="left_knee_link">
    <inertial>
      <origin xyz="0.005457 0.003964 -0.12074" rpy="0 0 0" />
      <mass value="1.932" />
      <inertia ixx="0.011329" ixy="4.82E-05" ixz="-4.49E-05" iyy="0.011277" iyz="-0.0007146" izz="0.0015168" />
    </inertial>
    <visual>
      <origin xyz="0 0 0" rpy="0 0 0" />
      <geometry>
        <mesh filename="meshes/left_knee_link.STL" />
      </geometry>
      <material name="white" />
    </visual>
    <collision>
      <origin xyz="0 0 0" rpy="0 0 0" />
      <geometry>
        <mesh filename="meshes/left_knee_link.STL" />
      </geometry>
    </collision>
  </link>
  <joint name="left_knee_joint" type="revolute">
    <origin xyz="-0.078273 0.0021489 -0.17734" rpy="0 0.1749 0" />
    <parent link="left_hip_yaw_link" />
    <child link="left_knee_link" />
    <axis xyz="0 1 0" />
    <limit lower="-0.087267" upper="2.8798" effort="139" velocity="20" />
  </joint>
  <link name="left_ankle_pitch_link">
    <inertial>
      <origin xyz="-0.007269 0 0.011137" rpy="0 0 0" />
      <mass value="0.074" />
      <inertia ixx="8.4E-06" ixy="0" ixz="-2.9E-06" iyy="1.89E-05" iyz="0" izz="1.26E-05" />
    </inertial>
    <visual>
      <origin xyz="0 0 0" rpy="0 0 0" />
      <geometry>
        <mesh filename="meshes/left_ankle_pitch_link.STL" />
      </geometry>
      <material name="white" />
    </visual>
    <collision>
      <origin xyz="0 0 0" rpy="0 0 0" />
      <geometry>
        <mesh filename="meshes/left_ankle_pitch_link.STL" />
      </geometry>
    </collision>
  </link>
  <joint name="left_ankle_pitch_joint" type="revolute">
    <origin xyz="0 -9.4445E-05 -0.30001" rpy="0 0 0" />
    <parent link="left_knee_link" />
    <child link="left_ankle_pitch_link" />
    <axis xyz="0 1 0" />
    <limit lower="-0.87267" upper="0.5236" effort="35" velocity="30" />
  </joint>
  <link name="left_ankle_roll_link">
    <inertial>
      <origin xyz="0.026505 0 -0.016425" rpy="0 0 0" />
      <mass value="0.608" />
      <inertia ixx="0.0002231" ixy="2E-07" ixz="8.91E-05" iyy="0.0016161" iyz="-1E-07" izz="0.0016667" />
    </inertial>
    <visual>
      <origin xyz="0 0 0" rpy="0 0 0" />
      <geometry>
        <mesh filename="meshes/left_ankle_roll_link.STL" />
      </geometry>
      <material name="dark" />
    </visual>
    <collision>
      <origin xyz="-0.05 0.025 -0.03" rpy="0 0 0" />
      <geometry>
        <sphere radius="0.005" />
      </geometry>
    </collision>
    <collision>
      <origin xyz="-0.05 -0.025 -0.03" rpy="0 0 0" />
      <geometry>
        <sphere radius="0.005" />
      </geometry>
    </collision>
    <collision>
      <origin xyz="0.12 0.03 -0.03" rpy="0 0 0" />
      <geometry>
        <sphere radius="0.005" />
      </geometry>
    </collision>
    <collision>
      <origin xyz="0.12 -0.03 -0.03" rpy="0 0 0" />
      <geometry>
        <sphere radius="0.005" />
      </geometry>
    </collision>
  </link>
  <joint name="left_ankle_roll_joint" type="revolute">
    <origin xyz="0 0 -0.017558" rpy="0 0 0" />
    <parent link="left_ankle_pitch_link" />
    <child link="left_ankle_roll_link" />
    <axis xyz="1 0 0" />
    <limit lower="-0.2618" upper="0.2618" effort="35" velocity="30" />
  </joint>
  <link name="right_hip_pitch_link">
    <inertial>
      <origin xyz="0.002741 -0.047791 -0.02606" rpy="0 0 0" />
      <mass value="1.35" />
      <inertia ixx="0.001811" ixy="-3.68E-05" ixz="-3.44E-05" iyy="0.0014193" iyz="-0.000171" izz="0.0012812" />
    </inertial>
    <visual>
      <origin xyz="0 0 0" rpy="0 0 0" />
      <geometry>
        <mesh filename="meshes/right_hip_pitch_link.STL" />
      </geometry>
      <material name="dark" />
    </visual>
    <collision>
      <origin xyz="0 0 0" rpy="0 0 0" />
      <geometry>
        <mesh filename="meshes/right_hip_pitch_link.STL" />
      </geometry>
    </collision>
  </link>
  <joint name="right_hip_pitch_joint" type="revolute">
    <origin xyz="0 -0.064452 -0.1027" rpy="0 0 0" />
    <parent link="pelvis" />
    <child link="right_hip_pitch_link" />
    <axis xyz="0 1 0" />
    <limit lower="-2.5307" upper="2.8798" effort="88" velocity="32" />
  </joint>
  <link name="right_hip_roll_link">
    <inertial>
      <origin xyz="0.029812 0.001045 -0.087934" rpy="0 0 0" />
      <mass value="1.52" />
      <inertia ixx="0.0023773" ixy="3.8E-06" ixz="-0.0003908" iyy="0.0024123" iyz="-1.84E-05" izz="0.0016595" />
    </inertial>
    <visual>
      <origin xyz="0 0 0" rpy="0 0 0" />
      <geometry>
        <mesh filename="meshes/right_hip_roll_link.STL" />
      </geometry>
      <material name="white" />
    </visual>
    <collision>
      <origin xyz="0 0 0" rpy="0 0 0" />
      <geometry>
        <mesh filename="meshes/right_hip_roll_link.STL" />
      </geometry>
    </collision>
  </link>
  <joint name="right_hip_roll_joint" type="revolute">
    <origin xyz="0 -0.052 -0.030465" rpy="0 -0.1749 0" />
    <parent link="right_hip_pitch_link" />
    <child link="right_hip_roll_link" />
    <axis xyz="1 0 0" />
    <limit lower="-2.9671" upper="0.5236" effort="139" velocity="20" />
  </joint>
  <link name="right_hip_yaw_link">
    <inertial>
      <origin xyz="-0.057709 0.010981 -0.15078" rpy="0 0 0" />
      <mass value="1.702" />
      <inertia ixx="0.0057774" ixy="0.0005411" ixz="-0.0023948" iyy="0.0076124" iyz="0.0007072" izz="0.003149" />
    </inertial>
    <visual>
      <origin xyz="0 0 0" rpy="0 0 0" />
      <geometry>
        <mesh filename="meshes/right_hip_yaw_link.STL" />
      </geometry>
      <material name="white" />
    </visual>
    <collision>
      <origin xyz="0 0 0" rpy="0 0 0" />
      <geometry>
        <mesh filename="meshes/right_hip_yaw_link.STL" />
      </geometry>
    </collision>
  </link>
  <joint name="right_hip_yaw_joint" type="revolute">
    <origin xyz="0.025001 0 -0.12412" rpy="0 0 0" />
    <parent link="right_hip_roll_link" />
    <child link="right_hip_yaw_link" />
    <axis xyz="0 0 1" />
    <limit lower="-2.7576" upper="2.7576" effort="88" velocity="32" />
  </joint>
  <link name="right_knee_link">
    <inertial>
      <origin xyz="0.005457 -0.003964 -0.12074" rpy="0 0 0" />
      <mass value="1.932" />
      <inertia ixx="0.011329" ixy="-4.82E-05" ixz="4.49E-05" iyy="0.011277" iyz="0.0007146" izz="0.0015168" />
    </inertial>
    <visual>
      <origin xyz="0 0 0" rpy="0 0 0" />
      <geometry>
        <mesh filename="meshes/right_knee_link.STL" />
      </geometry>
      <material name="white" />
    </visual>
    <collision>
      <origin xyz="0 0 0" rpy="0 0 0" />
      <geometry>
        <mesh filename="meshes/right_knee_link.STL" />
      </geometry>
    </collision>
  </link>
  <joint name="right_knee_joint" type="revolute">
    <origin xyz="-0.078273 -0.0021489 -0.17734" rpy="0 0.1749 0" />
    <parent link="right_hip_yaw_link" />
    <child link="right_knee_link" />
    <axis xyz="0 1 0" />
    <limit lower="-0.087267" upper="2.8798" effort="139" velocity="20" />
  </joint>
  <link name="right_ankle_pitch_link">
    <inertial>
      <origin xyz="-0.007269 0 0.011137" rpy="0 0 0" />
      <mass value="0.074" />
      <inertia ixx="8.4E-06" ixy="0" ixz="-2.9E-06" iyy="1.89E-05" iyz="0" izz="1.26E-05" />
    </inertial>
    <visual>
      <origin xyz="0 0 0" rpy="0 0 0" />
      <geometry>
        <mesh filename="meshes/right_ankle_pitch_link.STL" />
      </geometry>
      <material name="white" />
    </visual>
    <collision>
      <origin xyz="0 0 0" rpy="0 0 0" />
      <geometry>
        <mesh filename="meshes/right_ankle_pitch_link.STL" />
      </geometry>
    </collision>
  </link>
  <joint name="right_ankle_pitch_joint" type="revolute">
    <origin xyz="0 9.4445E-05 -0.30001" rpy="0 0 0" />
    <parent link="right_knee_link" />
    <child link="right_ankle_pitch_link" />
    <axis xyz="0 1 0" />
    <limit lower="-0.87267" upper="0.5236" effort="35" velocity="30" />
  </joint>
  <link name="right_ankle_roll_link">
    <inertial>
      <origin xyz="0.026505 0 -0.016425" rpy="0 0 0" />
      <mass value="0.608" />
      <inertia ixx="0.0002231" ixy="-2E-07" ixz="8.91E-05" iyy="0.0016161" iyz="1E-07" izz="0.0016667" />
    </inertial>
    <visual>
      <origin xyz="0 0 0" rpy="0 0 0" />
      <geometry>
        <mesh filename="meshes/right_ankle_roll_link.STL" />
      </geometry>
      <material name="dark" />
    </visual>
    <collision>
      <origin xyz="-0.05 0.025 -0.03" rpy="0 0 0" />
      <geometry>
        <sphere radius="0.005" />
      </geometry>
    </collision>
    <collision>
      <origin xyz="-0.05 -0.025 -0.03" rpy="0 0 0" />
      <geometry>
        <sphere radius="0.005" />
      </geometry>
    </collision>
    <collision>
      <origin xyz="0.12 0.03 -0.03" rpy="0 0 0" />
      <geometry>
        <sphere radius="0.005" />
      </geometry>
    </collision>
    <collision>
      <origin xyz="0.12 -0.03 -0.03" rpy="0 0 0" />
      <geometry>
        <sphere radius="0.005" />
      </geometry>
    </collision>
  </link>
  <joint name="right_ankle_roll_joint" type="revolute">
    <origin xyz="0 0 -0.017558" rpy="0 0 0" />
    <parent link="right_ankle_pitch_link" />
    <child link="right_ankle_roll_link" />
    <axis xyz="1 0 0" />
    <limit lower="-0.2618" upper="0.2618" effort="35" velocity="30" />
  </joint>

  
  <link name="waist_yaw_link">
    <inertial>
      <origin xyz="0.003494 0.000233 0.018034" rpy="0 0 0" />
      <mass value="0.214" />
      <inertia ixx="0.00010673" ixy="2.703E-06" ixz="-7.631E-06" iyy="0.00010422" iyz="-2.01E-07" izz="0.0001625" />
    </inertial>
    <visual>
      <origin xyz="0 0 0" rpy="0 0 0" />
      <geometry>
        <mesh filename="meshes/waist_yaw_link_rev_1_0.STL" />
      </geometry>
      <material name="white" />
    </visual>
  </link>
  <joint name="waist_yaw_joint" type="revolute">
    <origin xyz="0 0 0" rpy="0 0 0" />
    <parent link="pelvis" />
    <child link="waist_yaw_link" />
    <axis xyz="0 0 1" />
    <limit lower="-2.618" upper="2.618" effort="88" velocity="32" />
  </joint>
  <link name="waist_roll_link">
    <inertial>
      <origin xyz="0 2.3E-05 0" rpy="0 0 0" />
      <mass value="0.086" />
      <inertia ixx="7.079E-06" ixy="0" ixz="0" iyy="6.339E-06" iyz="0" izz="8.245E-06" />
    </inertial>
    <visual>
      <origin xyz="0 0 0" rpy="0 0 0" />
      <geometry>
        <mesh filename="meshes/waist_roll_link_rev_1_0.STL" />
      </geometry>
      <material name="white" />
    </visual>
  </link>
  <joint name="waist_roll_joint" type="revolute">
    <origin xyz="-0.0039635 0 0.044" rpy="0 0 0" />
    <parent link="waist_yaw_link" />
    <child link="waist_roll_link" />
    <axis xyz="1 0 0" />
    <limit lower="-0.52" upper="0.52" effort="35" velocity="30" />
  </joint>
  <link name="torso_link">
    <inertial>
      <origin xyz="0.000931 0.000346 0.15082" rpy="0 0 0" />
      <mass value="6.78" />
      <inertia ixx="0.05905" ixy="3.3302E-05" ixz="-0.0017715" iyy="0.047014" iyz="-2.2399E-05" izz="0.025652" />
    </inertial>
    <visual>
      <origin xyz="0 0 0" rpy="0 0 0" />
      <geometry>
        <mesh filename="meshes/torso_link_rev_1_0.STL" />
      </geometry>
      <material name="white" />
    </visual>
    <collision>
      <origin xyz="0 0 0" rpy="0 0 0" />
      <geometry>
        <mesh filename="meshes/torso_link_rev_1_0.STL" />
      </geometry>
    </collision>
  </link>
  <joint name="waist_pitch_joint" type="revolute">
    <origin xyz="0 0 0" rpy="0 0 0" />
    <parent link="waist_roll_link" />
    <child link="torso_link" />
    <axis xyz="0 1 0" />
    <limit lower="-0.52" upper="0.52" effort="35" velocity="30" />
  </joint>

  
  <joint name="logo_joint" type="fixed">
    <origin xyz="0.0039635 0 -0.044" rpy="0 0 0" />
    <parent link="torso_link" />
    <child link="logo_link" />
  </joint>
  <link name="logo_link">
    <inertial>
      <origin xyz="0 0 0" rpy="0 0 0" />
      <mass value="0.001" />
      <inertia ixx="1e-7" ixy="0" ixz="0" iyy="1e-7" iyz="0" izz="1e-7" />
    </inertial>
    <visual>
      <origin xyz="0 0 0" rpy="0 0 0" />
      <geometry>
        <mesh filename="meshes/logo_link.STL" />
      </geometry>
      <material name="dark" />
    </visual>
    <collision>
      <origin xyz="0 0 0" rpy="0 0 0" />
      <geometry>
        <mesh filename="meshes/logo_link.STL" />
      </geometry>
    </collision>
  </link>

  
  <link name="head_link">
    <inertial>
      <origin xyz="0.005267 0.000299 0.449869" rpy="0 0 0" />
      <mass value="1.036" />
      <inertia ixx="0.004085051" ixy="-2.543E-06" ixz="-6.9455E-05" iyy="0.004185212" iyz="-3.726E-06" izz="0.001807911" />
    </inertial>
    <visual>
      <origin xyz="0 0 0" rpy="0 0 0" />
      <geometry>
        <mesh filename="meshes/head_link.STL" />
      </geometry>
      <material name="dark" />
    </visual>
    <collision>
      <origin xyz="0 0 0" rpy="0 0 0" />
      <geometry>
        <mesh filename="meshes/head_link.STL" />
      </geometry>
    </collision>
  </link>
  <joint name="head_joint" type="fixed">
    <origin xyz="0.0039635 0 -0.044" rpy="0 0 0" />
    <parent link="torso_link" />
    <child link="head_link" />
  </joint>


  
  <link name="imu_in_torso" />
  <joint name="imu_in_torso_joint" type="fixed">
    <origin xyz="-0.03959 -0.00224 0.14792" rpy="0 0 0" />
    <parent link="torso_link" />
    <child link="imu_in_torso" />
  </joint>

  <link name="imu_in_pelvis" />
  <joint name="imu_in_pelvis_joint" type="fixed">
    <origin xyz="0.04525 0 -0.08339" rpy="0 0 0" />
    <parent link="pelvis" />
    <child link="imu_in_pelvis" />
  </joint>

  
  <link name="d435_link" />
  <joint name="d435_joint" type="fixed">
    <origin xyz="0.0576235 0.01753 0.42987" rpy="0 0.8307767239493009 0" />
    <parent link="torso_link" />
    <child link="d435_link" />
  </joint>

  
  <link name="mid360_link" />
  <joint name="mid360_joint" type="fixed">
    <origin xyz="0.0002835 0.00003 0.41618" rpy="0 0.04014257279586953 0" />
    <parent link="torso_link" />
    <child link="mid360_link" />
  </joint>

  
  <link name="left_shoulder_pitch_link">
    <inertial>
      <origin xyz="0 0.035892 -0.011628" rpy="0 0 0" />
      <mass value="0.718" />
      <inertia ixx="0.0004291" ixy="-9.2E-06" ixz="6.4E-06" iyy="0.000453" iyz="2.26E-05" izz="0.000423" />
    </inertial>
    <visual>
      <origin xyz="0 0 0" rpy="0 0 0" />
      <geometry>
        <mesh filename="meshes/left_shoulder_pitch_link.STL" />
      </geometry>
      <material name="white" />
    </visual>
    <collision>
      <origin xyz="0 0.04 -0.01" rpy="0 1.5707963267948966 0" />
      <geometry>
        <cylinder radius="0.03" length="0.05" />
      </geometry>
    </collision>
  </link>
  <joint name="left_shoulder_pitch_joint" type="revolute">
    <origin xyz="0.0039563 0.10022 0.24778" rpy="0.27931 5.4949E-05 -0.00019159" />
    <parent link="torso_link" />
    <child link="left_shoulder_pitch_link" />
    <axis xyz="0 1 0" />
    <limit lower="-3.0892" upper="2.6704" effort="25" velocity="37" />
  </joint>
  <link name="left_shoulder_roll_link">
    <inertial>
      <origin xyz="-0.000227 0.00727 -0.063243" rpy="0 0 0" />
      <mass value="0.643" />
      <inertia ixx="0.0006177" ixy="-1E-06" ixz="8.7E-06" iyy="0.0006912" iyz="-5.3E-06" izz="0.0003894" />
    </inertial>
    <visual>
      <origin xyz="0 0 0" rpy="0 0 0" />
      <geometry>
        <mesh filename="meshes/left_shoulder_roll_link.STL" />
      </geometry>
      <material name="white" />
    </visual>
    <collision>
      <origin xyz="-0.004 0.006 -0.053" rpy="0 0 0" />
      <geometry>
        <cylinder radius="0.03" length="0.03" />
      </geometry>
    </collision>
  </link>
  <joint name="left_shoulder_roll_joint" type="revolute">
    <origin xyz="0 0.038 -0.013831" rpy="-0.27925 0 0" />
    <parent link="left_shoulder_pitch_link" />
    <child link="left_shoulder_roll_link" />
    <axis xyz="1 0 0" />
    <limit lower="-1.5882" upper="2.2515" effort="25" velocity="37" />
  </joint>
  <link name="left_shoulder_yaw_link">
    <inertial>
      <origin xyz="0.010773 -0.002949 -0.072009" rpy="0 0 0" />
      <mass value="0.734" />
      <inertia ixx="0.0009988" ixy="7.9E-06" ixz="0.0001412" iyy="0.0010605" iyz="-2.86E-05" izz="0.0004354" />
    </inertial>
    <visual>
      <origin xyz="0 0 0" rpy="0 0 0" />
      <geometry>
        <mesh filename="meshes/left_shoulder_yaw_link.STL" />
      </geometry>
      <material name="white" />
    </visual>
    <collision>
      <origin xyz="0 0 0" rpy="0 0 0" />
      <geometry>
        <mesh filename="meshes/left_shoulder_yaw_link.STL" />
      </geometry>
    </collision>
  </link>
  <joint name="left_shoulder_yaw_joint" type="revolute">
    <origin xyz="0 0.00624 -0.1032" rpy="0 0 0" />
    <parent link="left_shoulder_roll_link" />
    <child link="left_shoulder_yaw_link" />
    <axis xyz="0 0 1" />
    <limit lower="-2.618" upper="2.618" effort="25" velocity="37" />
  </joint>
  <link name="left_elbow_link">
    <inertial>
      <origin xyz="0.064956 0.004454 -0.010062" rpy="0 0 0" />
      <mass value="0.6" />
      <inertia ixx="0.0002891" ixy="6.53E-05" ixz="1.72E-05" iyy="0.0004152" iyz="-5.6E-06" izz="0.0004197" />
    </inertial>
    <visual>
      <origin xyz="0 0 0" rpy="0 0 0" />
      <geometry>
        <mesh filename="meshes/left_elbow_link.STL" />
      </geometry>
      <material name="white" />
    </visual>
    <collision>
      <origin xyz="0 0 0" rpy="0 0 0" />
      <geometry>
        <mesh filename="meshes/left_elbow_link.STL" />
      </geometry>
    </collision>
  </link>
  <joint name="left_elbow_joint" type="revolute">
    <origin xyz="0.015783 0 -0.080518" rpy="0 0 0" />
    <parent link="left_shoulder_yaw_link" />
    <child link="left_elbow_link" />
    <axis xyz="0 1 0" />
    <limit lower="-1.0472" upper="2.0944" effort="25" velocity="37" />
  </joint>
  <joint name="left_wrist_roll_joint" type="revolute">
    <origin xyz="0.100 0.00188791 -0.010" rpy="0 0 0" />
    <axis xyz="1 0 0" />
    <parent link="left_elbow_link" />
    <child link="left_wrist_roll_link" />
    <limit effort="25" velocity="37" lower="-1.972222054" upper="1.972222054" />
  </joint>
  <link name="left_wrist_roll_link">
    <inertial>
      <origin xyz="0.01713944778 0.00053759094 0.00000048864" rpy="0 0 0" />
      <mass value="0.08544498" />
      <inertia ixx="0.00004821544023" ixy="-0.00000424511021" ixz="0.00000000510599" iyy="0.00003722899093" iyz="-0.00000000123525" izz="0.00005482106541" />
    </inertial>
    <visual>
      <origin xyz="0 0 0" rpy="0 0 0" />
      <geometry>
        <mesh filename="meshes/left_wrist_roll_link.STL" />
      </geometry>
      <material name="white" />
    </visual>
    <collision>
      <origin xyz="0 0 0" rpy="0 0 0" />
      <geometry>
        <mesh filename="meshes/left_wrist_roll_link.STL" />
      </geometry>
    </collision>
  </link>
  <joint name="left_wrist_pitch_joint" type="revolute">
    <origin xyz="0.038 0 0" rpy="0 0 0" />
    <axis xyz="0 1 0" />
    <parent link="left_wrist_roll_link" />
    <child link="left_wrist_pitch_link" />
    <limit effort="5" velocity="22" lower="-1.614429558" upper="1.614429558" />
  </joint>
  <link name="left_wrist_pitch_link">
    <inertial>
      <origin xyz="0.02299989837 -0.00111685314 -0.00111658096" rpy="0 0 0" />
      <mass value="0.48404956" />
      <inertia ixx="0.00016579646273" ixy="-0.00001231206746" ixz="0.00001231699194" iyy="0.00042954057410" iyz="0.00000081417712" izz="0.00042953697654" />
    </inertial>
    <visual>
      <origin xyz="0 0 0" rpy="0 0 0" />
      <geometry>
        <mesh filename="meshes/left_wrist_pitch_link.STL" />
      </geometry>
      <material name="white" />
    </visual>
    <collision>
      <origin xyz="0 0 0" rpy="0 0 0" />
      <geometry>
        <mesh filename="meshes/left_wrist_pitch_link.STL" />
      </geometry>
    </collision>
  </link>
  <joint name="left_wrist_yaw_joint" type="revolute">
    <origin xyz="0.046 0 0" rpy="0 0 0" />
    <axis xyz="0 0 1" />
    <parent link="left_wrist_pitch_link" />
    <child link="left_wrist_yaw_link" />
    <limit effort="5" velocity="22" lower="-1.614429558" upper="1.614429558" />
  </joint>
  <link name="left_wrist_yaw_link">
    <inertial>
      <origin xyz="0.02200381568 0.00049485096 0.00053861123" rpy="0 0 0" />
      <mass value="0.08457647" />
      <inertia ixx="0.00004929128828" ixy="-0.00000045735494" ixz="0.00000445867591" iyy="0.00005973338134" iyz="0.00000043217198" izz="0.00003928083826" />
    </inertial>
    <visual>
      <origin xyz="0 0 0" rpy="0 0 0" />
      <geometry>
        <mesh filename="meshes/left_wrist_yaw_link.STL" />
      </geometry>
      <material name="white" />
    </visual>
    <collision>
      <origin xyz="0 0 0" rpy="0 0 0" />
      <geometry>
        <mesh filename="meshes/left_wrist_yaw_link.STL" />
      </geometry>
    </collision>
  </link>
  <link name="right_shoulder_pitch_link">
    <inertial>
      <origin xyz="0 -0.035892 -0.011628" rpy="0 0 0" />
      <mass value="0.718" />
      <inertia ixx="0.0004291" ixy="9.2E-06" ixz="6.4E-06" iyy="0.000453" iyz="-2.26E-05" izz="0.000423" />
    </inertial>
    <visual>
      <origin xyz="0 0 0" rpy="0 0 0" />
      <geometry>
        <mesh filename="meshes/right_shoulder_pitch_link.STL" />
      </geometry>
      <material name="white" />
    </visual>
    <collision>
      <origin xyz="0 -0.04 -0.01" rpy="0 1.5707963267948966 0" />
      <geometry>
        <cylinder radius="0.03" length="0.05" />
      </geometry>
    </collision>
  </link>
  <joint name="right_shoulder_pitch_joint" type="revolute">
    <origin xyz="0.0039563 -0.10021 0.24778" rpy="-0.27931 5.4949E-05 0.00019159" />
    <parent link="torso_link" />
    <child link="right_shoulder_pitch_link" />
    <axis xyz="0 1 0" />
    <limit lower="-3.0892" upper="2.6704" effort="25" velocity="37" />
  </joint>
  <link name="right_shoulder_roll_link">
    <inertial>
      <origin xyz="-0.000227 -0.00727 -0.063243" rpy="0 0 0" />
      <mass value="0.643" />
      <inertia ixx="0.0006177" ixy="1E-06" ixz="8.7E-06" iyy="0.0006912" iyz="5.3E-06" izz="0.0003894" />
    </inertial>
    <visual>
      <origin xyz="0 0 0" rpy="0 0 0" />
      <geometry>
        <mesh filename="meshes/right_shoulder_roll_link.STL" />
      </geometry>
      <material name="white" />
    </visual>
    <collision>
      <origin xyz="-0.004 -0.006 -0.053" rpy="0 0 0" />
      <geometry>
        <cylinder radius="0.03" length="0.03" />
      </geometry>
    </collision>
  </link>
  <joint name="right_shoulder_roll_joint" type="revolute">
    <origin xyz="0 -0.038 -0.013831" rpy="0.27925 0 0" />
    <parent link="right_shoulder_pitch_link" />
    <child link="right_shoulder_roll_link" />
    <axis xyz="1 0 0" />
    <limit lower="-2.2515" upper="1.5882" effort="25" velocity="37" />
  </joint>
  <link name="right_shoulder_yaw_link">
    <inertial>
      <origin xyz="0.010773 0.002949 -0.072009" rpy="0 0 0" />
      <mass value="0.734" />
      <inertia ixx="0.0009988" ixy="-7.9E-06" ixz="0.0001412" iyy="0.0010605" iyz="2.86E-05" izz="0.0004354" />
    </inertial>
    <visual>
      <origin xyz="0 0 0" rpy="0 0 0" />
      <geometry>
        <mesh filename="meshes/right_shoulder_yaw_link.STL" />
      </geometry>
      <material name="white" />
    </visual>
    <collision>
      <origin xyz="0 0 0" rpy="0 0 0" />
      <geometry>
        <mesh filename="meshes/right_shoulder_yaw_link.STL" />
      </geometry>
    </collision>
  </link>
  <joint name="right_shoulder_yaw_joint" type="revolute">
    <origin xyz="0 -0.00624 -0.1032" rpy="0 0 0" />
    <parent link="right_shoulder_roll_link" />
    <child link="right_shoulder_yaw_link" />
    <axis xyz="0 0 1" />
    <limit lower="-2.618" upper="2.618" effort="25" velocity="37" />
  </joint>
  <link name="right_elbow_link">
    <inertial>
      <origin xyz="0.064956 -0.004454 -0.010062" rpy="0 0 0" />
      <mass value="0.6" />
      <inertia ixx="0.0002891" ixy="-6.53E-05" ixz="1.72E-05" iyy="0.0004152" iyz="5.6E-06" izz="0.0004197" />
    </inertial>
    <visual>
      <origin xyz="0 0 0" rpy="0 0 0" />
      <geometry>
        <mesh filename="meshes/right_elbow_link.STL" />
      </geometry>
      <material name="white" />
    </visual>
    <collision>
      <origin xyz="0 0 0" rpy="0 0 0" />
      <geometry>
        <mesh filename="meshes/right_elbow_link.STL" />
      </geometry>
    </collision>
  </link>
  <joint name="right_elbow_joint" type="revolute">
    <origin xyz="0.015783 0 -0.080518" rpy="0 0 0" />
    <parent link="right_shoulder_yaw_link" />
    <child link="right_elbow_link" />
    <axis xyz="0 1 0" />
    <limit lower="-1.0472" upper="2.0944" effort="25" velocity="37" />
  </joint>
  <joint name="right_wrist_roll_joint" type="revolute">
    <origin xyz="0.100 -0.00188791 -0.010" rpy="0 0 0" />
    <axis xyz="1 0 0" />
    <parent link="right_elbow_link" />
    <child link="right_wrist_roll_link" />
    <limit effort="25" velocity="37" lower="-1.972222054" upper="1.972222054" />
  </joint>
  <link name="right_wrist_roll_link">
    <inertial>
      <origin xyz="0.01713944778 -0.00053759094 0.00000048864" rpy="0 0 0" />
      <mass value="0.08544498" />
      <inertia ixx="0.00004821544023" ixy="0.00000424511021" ixz="0.00000000510599" iyy="0.00003722899093" iyz="0.00000000123525" izz="0.00005482106541" />
    </inertial>
    <visual>
      <origin xyz="0 0 0" rpy="0 0 0" />
      <geometry>
        <mesh filename="meshes/right_wrist_roll_link.STL" />
      </geometry>
      <material name="white" />
    </visual>
    <collision>
      <origin xyz="0 0 0" rpy="0 0 0" />
      <geometry>
        <mesh filename="meshes/right_wrist_roll_link.STL" />
      </geometry>
    </collision>
  </link>
  <joint name="right_wrist_pitch_joint" type="revolute">
    <origin xyz="0.038 0 0" rpy="0 0 0" />
    <axis xyz="0 1 0" />
    <parent link="right_wrist_roll_link" />
    <child link="right_wrist_pitch_link" />
    <limit effort="5" velocity="22" lower="-1.614429558" upper="1.614429558" />
  </joint>
  <link name="right_wrist_pitch_link">
    <inertial>
      <origin xyz="0.02299989837 0.00111685314 -0.00111658096" rpy="0 0 0" />
      <mass value="0.48404956" />
      <inertia ixx="0.00016579646273" ixy="0.00001231206746" ixz="0.00001231699194" iyy="0.00042954057410" iyz="-0.00000081417712" izz="0.00042953697654" />
    </inertial>
    <visual>
      <origin xyz="0 0 0" rpy="0 0 0" />
      <geometry>
        <mesh filename="meshes/right_wrist_pitch_link.STL" />
      </geometry>
      <material name="white" />
    </visual>
    <collision>
      <origin xyz="0 0 0" rpy="0 0 0" />
      <geometry>
        <mesh filename="meshes/right_wrist_pitch_link.STL" />
      </geometry>
    </collision>
  </link>
  <joint name="right_wrist_yaw_joint" type="revolute">
    <origin xyz="0.046 0 0" rpy="0 0 0" />
    <axis xyz="0 0 1" />
    <parent link="right_wrist_pitch_link" />
    <child link="right_wrist_yaw_link" />
    <limit effort="5" velocity="22" lower="-1.614429558" upper="1.614429558" />
  </joint>
  <link name="right_wrist_yaw_link">
    <inertial>
      <origin xyz="0.02200381568 -0.00049485096 0.00053861123" rpy="0 0 0" />
      <mass value="0.08457647" />
      <inertia ixx="0.00004929128828" ixy="0.00000045735494" ixz="0.00000445867591" iyy="0.00005973338134" iyz="-0.00000043217198" izz="0.00003928083826" />
    </inertial>
    <visual>
      <origin xyz="0 0 0" rpy="0 0 0" />
      <geometry>
        <mesh filename="meshes/right_wrist_yaw_link.STL" />
      </geometry>
      <material name="white" />
    </visual>
    <collision>
      <origin xyz="0 0 0" rpy="0 0 0" />
      <geometry>
        <mesh filename="meshes/right_wrist_yaw_link.STL" />
      </geometry>
    </collision>
  </link>

<joint name="left_hand_joint" type="fixed">
  <origin xyz="0.0415 0.003 0" rpy="0 -1.5708 0" />
  <parent link="left_wrist_yaw_link" />
  <child link="left_hand_link" />
</joint>

<joint name="right_hand_joint" type="fixed">
  <origin xyz="0.0415 -0.003 0" rpy="0 -1.5708 0" />
  <parent link="right_wrist_yaw_link" />
  <child link="right_hand_link" />
</joint>

  <link name="left_hand_link">
    <inertial>
      <origin xyz="-0.00718397232462035 -0.00342395518292698 -0.0584832405332602" rpy="0 0 0" />
      <mass value="0.529961023577223" />
      <inertia ixx="0.000480653113997558" ixy="5.6276926629699E-06" ixz="-4.05859709772904E-05" iyy="0.00067789113848308" iyz="-4.83494002678735E-06" izz="0.00034697306572534" />
    </inertial>
    <visual>
      <origin xyz="0 0 0" rpy="0 0 0" />
      <geometry>
        <mesh filename="./xhand/meshes/left_hand_link.STL" />
      </geometry>
      <material name="">
        <color rgba="0.866666666666667 0.866666666666667 0.890196078431372 1" />
      </material>
    </visual>
    <collision>
      <origin xyz="0 0 0" rpy="0 0 0" />
      <geometry>
        <mesh filename="./xhand/meshes/left_hand_link.STL" />
      </geometry>
    </collision>
  </link>

  <link name="left_hand_thumb_bend_link">
    <inertial>
      <origin xyz="0.0145290714760328 0.000901344264936247 -0.000127911758588877" rpy="0 0 0" />
      <mass value="0.0098553409170395" />
      <inertia ixx="5.42977914410068E-07" ixy="-1.16969836118924E-08" ixz="-3.74492329986334E-08" iyy="1.29130197093564E-06" iyz="-1.5496972766742E-09" izz="1.30457824480983E-06" />
    </inertial>
    <visual>
      <origin xyz="0 0 0" rpy="0 0 0" />
      <geometry>
        <mesh filename="./xhand/meshes/left_hand_thumb_bend_link.STL" />
      </geometry>
      <material name="">
        <color rgba="0.890196078431372 0.890196078431372 0.913725490196078 1" />
      </material>
    </visual>
    <collision>
      <origin xyz="0 0 0" rpy="0 0 0" />
      <geometry>
        <mesh filename="./xhand/meshes/left_hand_thumb_bend_link.STL" />
      </geometry>
    </collision>
  </link>
  <joint name="left_hand_thumb_bend_joint" type="revolute">
    <origin xyz="0.0228 -0.0095 -0.0305" rpy="0 0 0" />
    <parent link="left_hand_link" />
    <child link="left_hand_thumb_bend_link" />
    <axis xyz="0 0 -1" />
    <limit lower="0" upper="1.83" effort="1.1" velocity="8.63" />
    <dynamics damping="1" friction="1" />
  </joint>
  <link name="left_hand_thumb_rota_link1">
    <inertial>
      <origin xyz="0.0279279151977349 0.000121046050863875 -0.000277543472497595" rpy="0 0 0" />
      <mass value="0.153197010050709" />
      <inertia ixx="2.41523784234409E-05" ixy="6.62856100469595E-06" ixz="1.88729265232125E-07" iyy="4.7191218462316E-05" iyz="1.13949521391224E-07" izz="5.6212272955421E-05" />
    </inertial>
    <visual>
      <origin xyz="0 0 0" rpy="0 0 0" />
      <geometry>
        <mesh filename="./xhand/meshes/left_hand_thumb_rota_link1.STL" />
      </geometry>
      <material name="">
        <color rgba="1 1 1 1" />
      </material>
    </visual>
    <collision>
      <origin xyz="0 0 0" rpy="0 0 0" />
      <geometry>
        <mesh filename="./xhand/meshes/left_hand_thumb_rota_link1.STL" />
      </geometry>
    </collision>
  </link>
  <joint name="left_hand_thumb_rota_joint1" type="revolute">
    <origin xyz="0.028599 -0.0083177 0.00178" rpy="-0.2618 0 -0.0407" />
    <parent link="left_hand_thumb_bend_link" />
    <child link="left_hand_thumb_rota_link1" />
    <axis xyz="0 1 0" />
    <limit lower="-1.05" upper="1.57" effort="1.1" velocity="8.63" />
    <dynamics damping="1" friction="1" />
  </joint>
  <link name="left_hand_thumb_rota_link2">
    <inertial>
      <origin xyz="0.0224529466888815 0.000690615200902365 0.00314278985524262" rpy="0 0 0" />
      <mass value="0.0374009578136616" />
      <inertia ixx="3.98060244076823E-06" ixy="4.94846156827651E-07" ixz="1.18267329781539E-07" iyy="8.21784089346997E-06" iyz="6.13556519818818E-08" izz="9.54038333156961E-06" />
    </inertial>
    <visual>
      <origin xyz="0 0 0" rpy="0 0 0" />
      <geometry>
        <mesh filename="./xhand/meshes/left_hand_thumb_rota_link2.STL" />
      </geometry>
      <material name="">
        <color rgba="0.384313725490196 0.384313725490196 0.384313725490196 1" />
      </material>
    </visual>
    <collision>
      <origin xyz="0 0 0" rpy="0 0 0" />
      <geometry>
        <mesh filename="./xhand/meshes/left_hand_thumb_rota_link2.STL" />
      </geometry>
    </collision>
  </link>
  <joint name="left_hand_thumb_rota_joint2" type="revolute">
    <origin xyz="0.0553 0 0" rpy="0 0 0" />
    <parent link="left_hand_thumb_rota_link1" />
    <child link="left_hand_thumb_rota_link2" />
    <axis xyz="0 1 0" />
    <limit lower="-0.17" upper="1.83" effort="0.4" velocity="14.38" />
    <dynamics damping="1" friction="1" />
  </joint>
  <link name="left_hand_thumb_rota_tip">
    <inertial>
      <origin xyz="2.77555756156289E-17 8.24456234185811E-09 0.000270106204327401" rpy="0 0 0" />
      <mass value="3.53429173528852E-08" />
      <inertia ixx="9.35114688295086E-14" ixy="-1.32725847303435E-28" ixz="9.86076131526265E-32" iyy="3.97607820219959E-14" iyz="-1.58322857389778E-21" izz="9.35114688295086E-14" />
    </inertial>
    <visual>
      <origin xyz="0 0 0" rpy="0 0 0" />
      <geometry>
        <mesh filename="./xhand/meshes/left_hand_thumb_rota_tip.STL" />
      </geometry>
      <material name="">
        <color rgba="0.698039215686274 0.698039215686274 0.698039215686274 1" />
      </material>
    </visual>
    <collision>
      <origin xyz="0 0 0" rpy="0 0 0" />
      <geometry>
        <mesh filename="./xhand/meshes/left_hand_thumb_rota_tip.STL" />
      </geometry>
    </collision>
  </link>
  <joint name="left_hand_thumb_rota_joint3" type="fixed">
    <origin xyz="0.0504017317642718 0 0" rpy="0 0 0" />
    <parent link="left_hand_thumb_rota_link2" />
    <child link="left_hand_thumb_rota_tip" />
    <axis xyz="0 0 0" />
  </joint>
  <link name="left_hand_index_bend_link">
    <inertial>
      <origin xyz="-0.000134544831370011 -0.000675884062860156 0.00420851049165961" rpy="0 0 0" />
      <mass value="0.0677836037392838" />
      <inertia ixx="2.16567127431793E-05" ixy="1.17519873383444E-08" ixz="-8.90740188704384E-08" iyy="2.09681513604224E-05" iyz="6.68676922531736E-07" izz="3.39515033610064E-06" />
    </inertial>
    <visual>
      <origin xyz="0 0 0" rpy="0 0 0" />
      <geometry>
        <mesh filename="./xhand/meshes/left_hand_index_bend_link.STL" />
      </geometry>
      <material name="">
        <color rgba="0.988235294117647 0.737254901960784 0.517647058823529 1" />
      </material>
    </visual>
    <collision>
      <origin xyz="0 0 0" rpy="0 0 0" />
      <geometry>
        <mesh filename="./xhand/meshes/left_hand_index_bend_link.STL" />
      </geometry>
    </collision>
  </link>
  <joint name="left_hand_index_bend_joint" type="revolute">
    <origin xyz="0.0265 -0.0065 -0.0899" rpy="0 0 0" />
    <parent link="left_hand_link" />
    <child link="left_hand_index_bend_link" />
    <axis xyz="0 1 0" />
    <limit lower="-0.175" upper="0.175" effort="0.4" velocity="14.38" />
    <dynamics damping="1" friction="1" />
  </joint>
  <link name="left_hand_index_rota_link1">
    <inertial>
      <origin xyz="0.000139769333493966 0.000800517079915854 -0.0356038561271479" rpy="0 0 0" />
      <mass value="0.0630216014538817" />
      <inertia ixx="2.0518746365106E-05" ixy="7.80218143369854E-09" ixz="-4.29054701209884E-07" iyy="1.92422615292432E-05" iyz="-2.4702784768408E-07" izz="4.15027341232346E-06" />
    </inertial>
    <visual>
      <origin xyz="0 0 0" rpy="0 0 0" />
      <geometry>
        <mesh filename="./xhand/meshes/left_hand_index_rota_link1.STL" />
      </geometry>
      <material name="">
        <color rgba="1 1 1 1" />
      </material>
    </visual>
    <collision>
      <origin xyz="0 0 0" rpy="0 0 0" />
      <geometry>
        <mesh filename="./xhand/meshes/left_hand_index_rota_link1.STL" />
      </geometry>
    </collision>
  </link>
  <joint name="left_hand_index_joint1" type="revolute">
    <origin xyz="0 0 -0.0178" rpy="0 0 0" />
    <parent link="left_hand_index_bend_link" />
    <child link="left_hand_index_rota_link1" />
    <axis xyz="-1 0 0" />
    <limit lower="0" upper="1.92" effort="1.1" velocity="8.63" />
    <dynamics damping="1" friction="1" />
  </joint>
  <link name="left_hand_index_rota_link2">
    <inertial>
      <origin xyz="0.000338569414886528 -1.93676040351407E-05 -0.0231328539120741" rpy="0 0 0" />
      <mass value="0.0179923076570599" />
      <inertia ixx="3.01810067223025E-06" ixy="-4.92126455642096E-10" ixz="-9.09991288403927E-08" iyy="3.0198354354144E-06" iyz="-5.99900012810543E-08" izz="9.885388987729E-07" />
    </inertial>
    <visual>
      <origin xyz="0 0 0" rpy="0 0 0" />
      <geometry>
        <mesh filename="./xhand/meshes/left_hand_index_rota_link2.STL" />
      </geometry>
      <material name="">
        <color rgba="0.866666666666667 0.866666666666667 0.890196078431372 1" />
      </material>
    </visual>
    <collision>
      <origin xyz="0 0 0" rpy="0 0 0" />
      <geometry>
        <mesh filename="./xhand/meshes/left_hand_index_rota_link2.STL" />
      </geometry>
    </collision>
  </link>
  <joint name="left_hand_index_joint2" type="revolute">
    <origin xyz="0 0 -0.0558" rpy="0 0 0" />
    <parent link="left_hand_index_rota_link1" />
    <child link="left_hand_index_rota_link2" />
    <axis xyz="-1 0 0" />
    <limit lower="0" upper="1.92" effort="0.4" velocity="14.38" />
    <dynamics damping="1" friction="1" />
  </joint>
  <link name="left_hand_index_rota_tip">
    <inertial>
      <origin xyz="9.47159017883337E-16 -1.66550800928533E-14 0" rpy="0 0 0" />
      <mass value="3.53429173528852E-08" />
      <inertia ixx="3.97607820219958E-14" ixy="2.06598273810657E-28" ixz="3.39655762044409E-26" iyy="9.35114688295087E-14" iyz="-1.30578596099644E-40" izz="9.35114688295087E-14" />
    </inertial>
    <visual>
      <origin xyz="0 0 0" rpy="0 0 0" />
      <geometry>
        <mesh filename="./xhand/meshes/left_hand_index_rota_tip.STL" />
      </geometry>
      <material name="">
        <color rgba="0.698039215686274 0.698039215686274 0.698039215686274 1" />
      </material>
    </visual>
    <collision>
      <origin xyz="0 0 0" rpy="0 0 0" />
      <geometry>
        <mesh filename="./xhand/meshes/left_hand_index_rota_tip.STL" />
      </geometry>
    </collision>
  </link>
  <joint name="left_hand_index_rota_joint3" type="fixed">
    <origin xyz="0 0 -0.0424999999999991" rpy="0 0 0" />
    <parent link="left_hand_index_rota_link2" />
    <child link="left_hand_index_rota_tip" />
    <axis xyz="0 0 0" />
  </joint>
  <link name="left_hand_mid_link1">
    <inertial>
      <origin xyz="0.000139769503048257 0.00080051681932813 -0.0356038562198462" rpy="0 0 0" />
      <mass value="0.0630216000876532" />
      <inertia ixx="2.0518746354026E-05" ixy="7.80206454050682E-09" ixz="-4.29054815974796E-07" iyy="1.92422617602022E-05" iyz="-2.47027801809116E-07" izz="4.15027323551749E-06" />
    </inertial>
    <visual>
      <origin xyz="0 0 0" rpy="0 0 0" />
      <geometry>
        <mesh filename="./xhand/meshes/left_hand_mid_link1.STL" />
      </geometry>
      <material name="">
        <color rgba="1 1 1 1" />
      </material>
    </visual>
    <collision>
      <origin xyz="0 0 0" rpy="0 0 0" />
      <geometry>
        <mesh filename="./xhand/meshes/left_hand_mid_link1.STL" />
      </geometry>
    </collision>
  </link>
  <joint name="left_hand_mid_joint1" type="revolute">
    <origin xyz="0.004 -0.0065 -0.1082" rpy="0 0 0" />
    <parent link="left_hand_link" />
    <child link="left_hand_mid_link1" />
    <axis xyz="-1 0 0" />
    <limit lower="0" upper="1.92" effort="1.1" velocity="8.63" />
    <dynamics damping="1" friction="1" />
  </joint>
  <link name="left_hand_mid_link2">
    <inertial>
      <origin xyz="0.000338571504924487 -1.93625114516685E-05 -0.0231328477388325" rpy="0 0 0" />
      <mass value="0.0179922971238626" />
      <inertia ixx="3.01809863607458E-06" ixy="-4.91830289601756E-10" ixz="-9.09984854679422E-08" iyy="3.01983397037226E-06" iyz="-5.99889522310673E-08" izz="9.88538040128258E-07" />
    </inertial>
    <visual>
      <origin xyz="0 0 0" rpy="0 0 0" />
      <geometry>
        <mesh filename="./xhand/meshes/left_hand_mid_link2.STL" />
      </geometry>
      <material name="">
        <color rgba="0.866666666666667 0.866666666666667 0.890196078431372 1" />
      </material>
    </visual>
    <collision>
      <origin xyz="0 0 0" rpy="0 0 0" />
      <geometry>
        <mesh filename="./xhand/meshes/left_hand_mid_link2.STL" />
      </geometry>
    </collision>
  </link>
  <joint name="left_hand_mid_joint2" type="revolute">
    <origin xyz="0 0 -0.0558" rpy="0 0 0" />
    <parent link="left_hand_mid_link1" />
    <child link="left_hand_mid_link2" />
    <axis xyz="-1 0 0" />
    <limit lower="0" upper="1.92" effort="0.4" velocity="14.38" />
    <dynamics damping="1" friction="1" />
  </joint>
  <link name="left_hand_mid_tip">
    <inertial>
      <origin xyz="3.46944695195361E-18 -6.27969898303604E-15 0" rpy="0 0 0" />
      <mass value="3.53429173528852E-08" />
      <inertia ixx="3.97607820219958E-14" ixy="2.08752389989043E-28" ixz="2.52777196678215E-29" iyy="9.35114688295087E-14" iyz="-1.79366203433577E-43" izz="9.35114688295086E-14" />
    </inertial>
    <visual>
      <origin xyz="0 0 0" rpy="0 0 0" />
      <geometry>
        <mesh filename="./xhand/meshes/left_hand_mid_tip.STL" />
      </geometry>
      <material name="">
        <color rgba="0.698039215686274 0.698039215686274 0.698039215686274 1" />
      </material>
    </visual>
    <collision>
      <origin xyz="0 0 0" rpy="0 0 0" />
      <geometry>
        <mesh filename="./xhand/meshes/left_hand_mid_tip.STL" />
      </geometry>
    </collision>
  </link>
  <joint name="left_hand_mid_joint3" type="fixed">
    <origin xyz="0 0 -0.0424999999999995" rpy="0 0 0" />
    <parent link="left_hand_mid_link2" />
    <child link="left_hand_mid_tip" />
    <axis xyz="0 0 0" />
  </joint>
  <link name="left_hand_ring_link1">
    <inertial>
      <origin xyz="0.000139769503829958 0.00080051746545018 -0.0356038550320788" rpy="0 0 0" />
      <mass value="0.0630216034004235" />
      <inertia ixx="2.05187480603073E-05" ixy="7.80204473072652E-09" ixz="-4.29055143702643E-07" iyy="1.92422630398686E-05" iyz="-2.47028634316192E-07" izz="4.15027377034858E-06" />
    </inertial>
    <visual>
      <origin xyz="0 0 0" rpy="0 0 0" />
      <geometry>
        <mesh filename="./xhand/meshes/left_hand_ring_link1.STL" />
      </geometry>
      <material name="">
        <color rgba="1 1 1 1" />
      </material>
    </visual>
    <collision>
      <origin xyz="0 0 0" rpy="0 0 0" />
      <geometry>
        <mesh filename="./xhand/meshes/left_hand_ring_link1.STL" />
      </geometry>
    </collision>
  </link>
  <joint name="left_hand_ring_joint1" type="revolute">
    <origin xyz="-0.016 -0.0065 -0.1052" rpy="0 0 0" />
    <parent link="left_hand_link" />
    <child link="left_hand_ring_link1" />
    <axis xyz="-1 0 0" />
    <limit lower="0" upper="1.92" effort="1.1" velocity="8.63" />
    <dynamics damping="1" friction="1" />
  </joint>
  <link name="left_hand_ring_link2">
    <inertial>
      <origin xyz="0.000338569362970571 -1.93675642107764E-05 -0.0231328537916428" rpy="0 0 0" />
      <mass value="0.0179923074393582" />
      <inertia ixx="3.01810064426992E-06" ixy="-4.92130070945092E-10" ixz="-9.09991388750487E-08" iyy="3.0198354064253E-06" iyz="-5.99899932123125E-08" izz="9.88538891512388E-07" />
    </inertial>
    <visual>
      <origin xyz="0 0 0" rpy="0 0 0" />
      <geometry>
        <mesh filename="./xhand/meshes/left_hand_ring_link2.STL" />
      </geometry>
      <material name="">
        <color rgba="0.866666666666667 0.866666666666667 0.890196078431372 1" />
      </material>
    </visual>
    <collision>
      <origin xyz="0 0 0" rpy="0 0 0" />
      <geometry>
        <mesh filename="./xhand/meshes/left_hand_ring_link2.STL" />
      </geometry>
    </collision>
  </link>
  <joint name="left_hand_ring_joint2" type="revolute">
    <origin xyz="0 0 -0.0558" rpy="0 0 0" />
    <parent link="left_hand_ring_link1" />
    <child link="left_hand_ring_link2" />
    <axis xyz="-1 0 0" />
    <limit lower="0" upper="1.92" effort="0.4" velocity="14.38" />
    <dynamics damping="1" friction="1" />
  </joint>
  <link name="left_hand_ring_tip">
    <inertial>
      <origin xyz="3.46944695195361E-18 -6.36816988031086E-15 0" rpy="0 0 0" />
      <mass value="3.53429173528852E-08" />
      <inertia ixx="3.97607820219958E-14" ixy="2.08752389989043E-28" ixz="2.52777196678215E-29" iyy="9.35114688295087E-14" iyz="-1.79366203433577E-43" izz="9.35114688295087E-14" />
    </inertial>
    <visual>
      <origin xyz="0 0 0" rpy="0 0 0" />
      <geometry>
        <mesh filename="./xhand/meshes/left_hand_ring_tip.STL" />
      </geometry>
      <material name="">
        <color rgba="0.698039215686274 0.698039215686274 0.698039215686274 1" />
      </material>
    </visual>
    <collision>
      <origin xyz="0 0 0" rpy="0 0 0" />
      <geometry>
        <mesh filename="./xhand/meshes/left_hand_ring_tip.STL" />
      </geometry>
    </collision>
  </link>
  <joint name="left_hand_ring_joint3" type="fixed">
    <origin xyz="0 0 -0.0425" rpy="0 0 0" />
    <parent link="left_hand_ring_link2" />
    <child link="left_hand_ring_tip" />
    <axis xyz="0 0 0" />
  </joint>
  <link name="left_hand_pinky_link1">
    <inertial>
      <origin xyz="0.000139769403140894 0.000800517208403269 -0.0356038550457389" rpy="0 0 0" />
      <mass value="0.0630216018833023" />
      <inertia ixx="2.05187477543832E-05" ixy="7.80212984947717E-09" ixz="-4.29055030397585E-07" iyy="1.92422628106822E-05" iyz="-2.47028571410968E-07" izz="4.15027354474908E-06" />
    </inertial>
    <visual>
      <origin xyz="0 0 0" rpy="0 0 0" />
      <geometry>
        <mesh filename="./xhand/meshes/left_hand_pinky_link1.STL" />
      </geometry>
      <material name="">
        <color rgba="1 1 1 1" />
      </material>
    </visual>
    <collision>
      <origin xyz="0 0 0" rpy="0 0 0" />
      <geometry>
        <mesh filename="./xhand/meshes/left_hand_pinky_link1.STL" />
      </geometry>
    </collision>
  </link>
  <joint name="left_hand_pinky_joint1" type="revolute">
    <origin xyz="-0.036 -0.0065 -0.1022" rpy="0 0 0" />
    <parent link="left_hand_link" />
    <child link="left_hand_pinky_link1" />
    <axis xyz="-1 0 0" />
    <limit lower="0" upper="1.92" effort="1.1" velocity="8.63" />
    <dynamics damping="1" friction="1" />
  </joint>
  <link name="left_hand_pinky_link2">
    <inertial>
      <origin xyz="0.000338573187645894 -1.93618349248192E-05 -0.0231328439241562" rpy="0 0 0" />
      <mass value="0.0179922893932107" />
      <inertia ixx="3.01809788005842E-06" ixy="-4.91751568021702E-10" ixz="-9.09983567107085E-08" iyy="3.0198329418105E-06" iyz="-5.99887920223039E-08" izz="9.8853806652991E-07" />
    </inertial>
    <visual>
      <origin xyz="0 0 0" rpy="0 0 0" />
      <geometry>
        <mesh filename="./xhand/meshes/left_hand_pinky_link2.STL" />
      </geometry>
      <material name="">
        <color rgba="0.866666666666667 0.866666666666667 0.890196078431372 1" />
      </material>
    </visual>
    <collision>
      <origin xyz="0 0 0" rpy="0 0 0" />
      <geometry>
        <mesh filename="./xhand/meshes/left_hand_pinky_link2.STL" />
      </geometry>
    </collision>
  </link>
  <joint name="left_hand_pinky_joint2" type="revolute">
    <origin xyz="0 0 -0.0558" rpy="0 0 0" />
    <parent link="left_hand_pinky_link1" />
    <child link="left_hand_pinky_link2" />
    <axis xyz="-1 0 0" />
    <limit lower="0" upper="1.92" effort="0.4" velocity="14.38" />
    <dynamics damping="1" friction="1" />
  </joint>
  <link name="left_hand_pinky_tip">
    <inertial>
      <origin xyz="1.38777878078145E-17 -8.99974539336768E-15 0" rpy="0 0 0" />
      <mass value="3.53429173528851E-08" />
      <inertia ixx="3.97607820219958E-14" ixy="2.08752389989043E-28" ixz="2.52777196678213E-29" iyy="9.35114688295085E-14" iyz="-1.79366203433577E-43" izz="9.35114688295085E-14" />
    </inertial>
    <visual>
      <origin xyz="0 0 0" rpy="0 0 0" />
      <geometry>
        <mesh filename="./xhand/meshes/left_hand_pinky_tip.STL" />
      </geometry>
      <material name="">
        <color rgba="0.698039215686274 0.698039215686274 0.698039215686274 1" />
      </material>
    </visual>
    <collision>
      <origin xyz="0 0 0" rpy="0 0 0" />
      <geometry>
        <mesh filename="./xhand/meshes/left_hand_pinky_tip.STL" />
      </geometry>
    </collision>
  </link>
  <joint name="left_hand_pinky_joint3" type="fixed">
    <origin xyz="0 0 -0.0424999999999995" rpy="0 0 0" />
    <parent link="left_hand_pinky_link2" />
    <child link="left_hand_pinky_tip" />
    <axis xyz="0 0 0" />
  </joint> 

  <link name="right_hand_link">
    <inertial>
      <origin xyz="-0.00713969600456059 0.00342243593256283 -0.0584806731230685" rpy="0 0 0" />
      <mass value="0.530025137189824" />
      <inertia ixx="0.000480675299127658" ixy="-5.70774350447044E-06" ixz="-3.94757992682007E-05" iyy="0.000677544052393642" iyz="4.84926198036181E-06" izz="0.000346610500441846" />
    </inertial>
    <visual>
      <origin xyz="0 0 0" rpy="0 0 0" />
      <geometry>
        <mesh filename="./xhand/meshes/right_hand_link.STL" />
      </geometry>
      <material name="">
        <color rgba="0.792156862745098 0.819607843137255 0.933333333333333 1" />
      </material>
    </visual>
    <collision>
      <origin xyz="0 0 0" rpy="0 0 0" />
      <geometry>
        <mesh filename="./xhand/meshes/right_hand_link.STL" />
      </geometry>
    </collision>
  </link>
  <link name="right_hand_thumb_bend_link">
    <inertial>
      <origin xyz="0.0145290801349471 -0.000901302744009009 -0.000127925728837824" rpy="0 0 0" />
      <mass value="0.0098552942780609" />
      <inertia ixx="5.42973961076784E-07" ixy="1.1697377817489E-08" ixz="-3.74480550329303E-08" iyy="1.29129949885877E-06" iyz="1.54918667172288E-09" izz="1.30457450474268E-06" />
    </inertial>
    <visual>
      <origin xyz="0 0 0" rpy="0 0 0" />
      <geometry>
        <mesh filename="./xhand/meshes/right_hand_thumb_bend_link.STL" />
      </geometry>
      <material name="">
        <color rgba="0.890196078431372 0.890196078431372 0.913725490196078 1" />
      </material>
    </visual>
    <collision>
      <origin xyz="0 0 0" rpy="0 0 0" />
      <geometry>
        <mesh filename="./xhand/meshes/right_hand_thumb_bend_link.STL" />
      </geometry>
    </collision>
  </link>
  <joint name="right_hand_thumb_bend_joint" type="revolute">
    <origin xyz="0.0228 0.0095 -0.0305" rpy="0 0 0" />
    <parent link="right_hand_link" />
    <child link="right_hand_thumb_bend_link" />
    <axis xyz="0 0 1" />
    <limit lower="0" upper="1.83" effort="1.1" velocity="8.63" />
    <dynamics damping="1" friction="1" />
  </joint>
  <link name="right_hand_thumb_rota_link1">
    <inertial>
      <origin xyz="0.0279237160722458 -0.000127602868102849 -0.000272577361780019" rpy="0 0 0" />
      <mass value="0.153264803291678" />
      <inertia ixx="2.4165365258545E-05" ixy="-6.63197358473128E-06" ixz="1.94475216115701E-07" iyy="4.72108607465942E-05" iyz="-1.01931561408839E-07" izz="5.62288901300273E-05" />
    </inertial>
    <visual>
      <origin xyz="0 0 0" rpy="0 0 0" />
      <geometry>
        <mesh filename="./xhand/meshes/right_hand_thumb_rota_link1.STL" />
      </geometry>
      <material name="">
        <color rgba="1 1 1 1" />
      </material>
    </visual>
    <collision>
      <origin xyz="0 0 0" rpy="0 0 0" />
      <geometry>
        <mesh filename="./xhand/meshes/right_hand_thumb_rota_link1.STL" />
      </geometry>
    </collision>
  </link>
  <joint name="right_hand_thumb_rota_joint1" type="revolute">
    <origin xyz="0.028599 0.0083177 0.00178" rpy="0.2618 0 0.0407" />
    <parent link="right_hand_thumb_bend_link" />
    <child link="right_hand_thumb_rota_link1" />
    <axis xyz="0 1 0" />
    <limit lower="-1.05" upper="1.57" effort="1.1" velocity="8.63" />
    <dynamics damping="1" friction="1" />
  </joint>
  <link name="right_hand_thumb_rota_link2">
    <inertial>
      <origin xyz="0.0224697187075982 -0.000691342225602463 0.00302232046900801" rpy="0 0 0" />
      <mass value="0.0374003730407777" />
      <inertia ixx="3.98187483395831E-06" ixy="-4.9463629774215E-07" ixz="1.48034880030095E-07" iyy="8.21760971089748E-06" iyz="-5.85388102153786E-08" izz="9.53856476569885E-06" />
    </inertial>
    <visual>
      <origin xyz="0 0 0" rpy="0 0 0" />
      <geometry>
        <mesh filename="./xhand/meshes/right_hand_thumb_rota_link2.STL" />
      </geometry>
      <material name="">
        <color rgba="0.792156862745098 0.819607843137255 0.933333333333333 1" />
      </material>
    </visual>
    <collision>
      <origin xyz="0 0 0" rpy="0 0 0" />
      <geometry>
        <mesh filename="./xhand/meshes/right_hand_thumb_rota_link2.STL" />
      </geometry>
    </collision>
  </link>
  <joint name="right_hand_thumb_rota_joint2" type="revolute">
    <origin xyz="0.0553 0 0" rpy="0 0 0" />
    <parent link="right_hand_thumb_rota_link1" />
    <child link="right_hand_thumb_rota_link2" />
    <axis xyz="0 1 0" />
    <limit lower="-0.175" upper="1.83" effort="0.4" velocity="14.38" />
    <dynamics damping="1" friction="1" />
  </joint>
  <link name="right_hand_thumb_rota_tip">
    <inertial>
      <origin xyz="8.28680735143195E-10 -8.2445667376474E-09 2.77555756156289E-16" rpy="0 0 0" />
      <mass value="3.53429173528852E-08" />
      <inertia ixx="9.35114688295028E-14" ixy="1.78168632222544E-20" ixz="5.02898827078395E-30" iyy="3.97607820220018E-14" iyz="-6.5475455133344E-29" izz="9.35114688295088E-14" />
    </inertial>
    <visual>
      <origin xyz="0 0 0" rpy="0 0 0" />
      <geometry>
        <mesh filename="./xhand/meshes/right_hand_thumb_rota_tip.STL" />
      </geometry>
      <material name="">
        <color rgba="0.698039215686274 0.698039215686274 0.698039215686274 1" />
      </material>
    </visual>
    <collision>
      <origin xyz="0 0 0" rpy="0 0 0" />
      <geometry>
        <mesh filename="./xhand/meshes/right_hand_thumb_rota_tip.STL" />
      </geometry>
    </collision>
  </link>
  <joint name="right_hand_thumb_rota_joint3" type="fixed">
    <origin xyz="0.0504024546888781 0 0" rpy="0 0 0" />
    <parent link="right_hand_thumb_rota_link2" />
    <child link="right_hand_thumb_rota_tip" />
    <axis xyz="0 0 0" />
  </joint>
  <link name="right_hand_index_bend_link">
    <inertial>
      <origin xyz="8.08448802515592E-05 0.000675884062860609 0.00420851049166139" rpy="0 0 0" />
      <mass value="0.0677836037392839" />
      <inertia ixx="2.16567127431793E-05" ixy="9.29177767371407E-09" ixz="2.1345292815894E-07" iyy="2.09689353738481E-05" iyz="-6.68676922531782E-07" izz="3.39593434952634E-06" />
    </inertial>
    <visual>
      <origin xyz="0 0 0" rpy="0 0 0" />
      <geometry>
        <mesh filename="./xhand/meshes/right_hand_index_bend_link.STL" />
      </geometry>
      <material name="">
        <color rgba="0.43921568627451 0.43921568627451 0.43921568627451 1" />
      </material>
    </visual>
    <collision>
      <origin xyz="0 0 0" rpy="0 0 0" />
      <geometry>
        <mesh filename="./xhand/meshes/right_hand_index_bend_link.STL" />
      </geometry>
    </collision>
  </link>
  <joint name="right_hand_index_bend_joint" type="revolute">
    <origin xyz="0.0265 0.0065 -0.0899" rpy="0 0 0" />
    <parent link="right_hand_link" />
    <child link="right_hand_index_bend_link" />
    <axis xyz="0 1 0" />
    <limit lower="-0.175" upper="0.175" effort="0.4" velocity="14.38" />
    <dynamics damping="1" friction="1" />
  </joint>
  <link name="right_hand_index_rota_link1">
    <inertial>
      <origin xyz="-0.000139769529292743 -0.0008005173406112 -0.0356038554391181" rpy="0 0 0" />
      <mass value="0.0630216027459696" />
      <inertia ixx="2.05187473304044E-05" ixy="7.80203520045171E-09" ixz="4.29054958401514E-07" iyy="1.92422623666435E-05" iyz="2.47028335879796E-07" izz="4.15027364465252E-06" />
    </inertial>
    <visual>
      <origin xyz="0 0 0" rpy="0 0 0" />
      <geometry>
        <mesh filename="./xhand/meshes/right_hand_index_rota_link1.STL" />
      </geometry>
      <material name="">
        <color rgba="1 1 1 1" />
      </material>
    </visual>
    <collision>
      <origin xyz="0 0 0" rpy="0 0 0" />
      <geometry>
        <mesh filename="./xhand/meshes/right_hand_index_rota_link1.STL" />
      </geometry>
    </collision>
  </link>
  <joint name="right_hand_index_joint1" type="revolute">
    <origin xyz="0 0 -0.0178" rpy="0 0 0" />
    <parent link="right_hand_index_bend_link" />
    <child link="right_hand_index_rota_link1" />
    <axis xyz="1 0 0" />
    <limit lower="0" upper="1.92" effort="1.1" velocity="8.63" />
    <dynamics damping="1" friction="1" />
  </joint>
  <link name="right_hand_index_rota_link2">
    <inertial>
      <origin xyz="-0.000338569409191088 1.93676000460963E-05 -0.0231328539090889" rpy="0 0 0" />
      <mass value="0.0179923076356481" />
      <inertia ixx="3.01810066952146E-06" ixy="-4.92126710010375E-10" ixz="9.0999129965313E-08" iyy="3.01983543305207E-06" iyz="5.99900021060723E-08" izz="9.88538897829343E-07" />
    </inertial>
    <visual>
      <origin xyz="0 0 0" rpy="0 0 0" />
      <geometry>
        <mesh filename="./xhand/meshes/right_hand_index_rota_link2.STL" />
      </geometry>
      <material name="">
        <color rgba="0.866666666666667 0.866666666666667 0.890196078431372 1" />
      </material>
    </visual>
    <collision>
      <origin xyz="0 0 0" rpy="0 0 0" />
      <geometry>
        <mesh filename="./xhand/meshes/right_hand_index_rota_link2.STL" />
      </geometry>
    </collision>
  </link>
  <joint name="right_hand_index_joint2" type="revolute">
    <origin xyz="0 0 -0.0558" rpy="0 0 0" />
    <parent link="right_hand_index_rota_link1" />
    <child link="right_hand_index_rota_link2" />
    <axis xyz="1 0 0" />
    <limit lower="0" upper="1.92" effort="0.4" velocity="14.38" />
    <dynamics damping="1" friction="1" />
  </joint>
  <link name="right_hand_index_rota_tip">
    <inertial>
      <origin xyz="-2.98372437868011E-16 4.86850143532891E-15 -2.77555756156289E-17" rpy="0 0 0" />
      <mass value="3.53429173528852E-08" />
      <inertia ixx="3.97607820219958E-14" ixy="4.31827422870135E-29" ixz="1.6690203866884E-29" iyy="9.35114688295087E-14" iyz="1.37887768889562E-41" izz="9.35114688295087E-14" />
    </inertial>
    <visual>
      <origin xyz="0 0 0" rpy="0 0 0" />
      <geometry>
        <mesh filename="./xhand/meshes/right_hand_index_rota_tip.STL" />
      </geometry>
      <material name="">
        <color rgba="0.698039215686274 0.698039215686274 0.698039215686274 1" />
      </material>
    </visual>
    <collision>
      <origin xyz="0 0 0" rpy="0 0 0" />
      <geometry>
        <mesh filename="./xhand/meshes/right_hand_index_rota_tip.STL" />
      </geometry>
    </collision>
  </link>
  <joint name="right_hand_index_rota_joint3" type="fixed">
    <origin xyz="0 0 -0.0424999999999993" rpy="0 0 0" />
    <parent link="right_hand_index_rota_link2" />
    <child link="right_hand_index_rota_tip" />
    <axis xyz="0 0 0" />
  </joint>
  <link name="right_hand_mid_link1">
    <inertial>
      <origin xyz="-0.000139769452255069 -0.000800516966578778 -0.0356038561997856" rpy="0 0 0" />
      <mass value="0.0630216005457211" />
      <inertia ixx="2.05187463723375E-05" ixy="7.80208491082156E-09" ixz="4.29054729251827E-07" iyy="1.92422616109533E-05" iyz="2.47027898316091E-07" izz="4.15027334868904E-06" />
    </inertial>
    <visual>
      <origin xyz="0 0 0" rpy="0 0 0" />
      <geometry>
        <mesh filename="./xhand/meshes/right_hand_mid_link1.STL" />
      </geometry>
      <material name="">
        <color rgba="1 1 1 1" />
      </material>
    </visual>
    <collision>
      <origin xyz="0 0 0" rpy="0 0 0" />
      <geometry>
        <mesh filename="./xhand/meshes/right_hand_mid_link1.STL" />
      </geometry>
    </collision>
  </link>
  <joint name="right_hand_mid_joint1" type="revolute">
    <origin xyz="0.004 0.0065 -0.1082" rpy="0 0 0" />
    <parent link="right_hand_link" />
    <child link="right_hand_mid_link1" />
    <axis xyz="1 0 0" />
    <limit lower="0" upper="1.92" effort="1.1" velocity="8.63" />
    <dynamics damping="1" friction="1" />
  </joint>
  <link name="right_hand_mid_link2">
    <inertial>
      <origin xyz="-0.000338569410644367 1.93676002657236E-05 -0.0231328539105626" rpy="0 0 0" />
      <mass value="0.0179923076388667" />
      <inertia ixx="3.01810066972044E-06" ixy="-4.92126597550988E-10" ixz="9.09991296960493E-08" iyy="3.01983543347029E-06" iyz="5.99900021064019E-08" izz="9.88538897954892E-07" />
    </inertial>
    <visual>
      <origin xyz="0 0 0" rpy="0 0 0" />
      <geometry>
        <mesh filename="./xhand/meshes/right_hand_mid_link2.STL" />
      </geometry>
      <material name="">
        <color rgba="0.866666666666667 0.866666666666667 0.890196078431372 1" />
      </material>
    </visual>
    <collision>
      <origin xyz="0 0 0" rpy="0 0 0" />
      <geometry>
        <mesh filename="./xhand/meshes/right_hand_mid_link2.STL" />
      </geometry>
    </collision>
  </link>
  <joint name="right_hand_mid_joint2" type="revolute">
    <origin xyz="0 0 -0.0558" rpy="0 0 0" />
    <parent link="right_hand_mid_link1" />
    <child link="right_hand_mid_link2" />
    <axis xyz="1 0 0" />
    <limit lower="0" upper="1.92" effort="0.4" velocity="14.38" />
    <dynamics damping="1" friction="1" />
  </joint>
  <link name="right_hand_mid_tip">
    <inertial>
      <origin xyz="8.67361737988404E-19 6.7992486640911E-15 -0.000393026889207115" rpy="0 0 0" />
      <mass value="3.53429173528852E-08" />
      <inertia ixx="3.97607820219958E-14" ixy="4.6998091400205E-29" ixz="1.72625026613961E-29" iyy="9.35114688295087E-14" iyz="-1.34632261157722E-30" izz="9.35114688295087E-14" />
    </inertial>
    <visual>
      <origin xyz="0 0 0" rpy="0 0 0" />
      <geometry>
        <mesh filename="./xhand/meshes/right_hand_mid_tip.STL" />
      </geometry>
      <material name="">
        <color rgba="0.698039215686274 0.698039215686274 0.698039215686274 1" />
      </material>
    </visual>
    <collision>
      <origin xyz="0 0 0" rpy="0 0 0" />
      <geometry>
        <mesh filename="./xhand/meshes/right_hand_mid_tip.STL" />
      </geometry>
    </collision>
  </link>
  <joint name="right_hand_mid_joint3" type="fixed">
    <origin xyz="0 0 -0.042107" rpy="0 0 0" />
    <parent link="right_hand_mid_link2" />
    <child link="right_hand_mid_tip" />
    <axis xyz="0 0 0" />
  </joint>
  <link name="right_hand_ring_link1">
    <inertial>
      <origin xyz="-0.000139769594263359 -0.000800517227339018 -0.0356038552802108" rpy="0 0 0" />
      <mass value="0.0630216021699602" />
      <inertia ixx="2.05187476755252E-05" ixy="7.80199293997393E-09" ixz="4.29055082722493E-07" iyy="1.92422628261764E-05" iyz="2.47028487672885E-07" izz="4.15027358505553E-06" />
    </inertial>
    <visual>
      <origin xyz="0 0 0" rpy="0 0 0" />
      <geometry>
        <mesh filename="./xhand/meshes/right_hand_ring_link1.STL" />
      </geometry>
      <material name="">
        <color rgba="1 1 1 1" />
      </material>
    </visual>
    <collision>
      <origin xyz="0 0 0" rpy="0 0 0" />
      <geometry>
        <mesh filename="./xhand/meshes/right_hand_ring_link1.STL" />
      </geometry>
    </collision>
  </link>
  <joint name="right_hand_ring_joint1" type="revolute">
    <origin xyz="-0.016 0.0065 -0.1052" rpy="0 0 0" />
    <parent link="right_hand_link" />
    <child link="right_hand_ring_link1" />
    <axis xyz="1 0 0" />
    <limit lower="0" upper="1.92" effort="1.1" velocity="8.63" />
    <dynamics damping="1" friction="1" />
  </joint>
  <link name="right_hand_ring_link2">
    <inertial>
      <origin xyz="-0.00033857292489315 1.9362209649449E-05 -0.0231328478093387" rpy="0 0 0" />
      <mass value="0.0179922978524175" />
      <inertia ixx="3.01809858290111E-06" ixy="-4.91620007394315E-10" ixz="9.09983307330798E-08" iyy="3.01983382489043E-06" iyz="5.99889823171253E-08" izz="9.88537681686488E-07" />
    </inertial>
    <visual>
      <origin xyz="0 0 0" rpy="0 0 0" />
      <geometry>
        <mesh filename="./xhand/meshes/right_hand_ring_link2.STL" />
      </geometry>
      <material name="">
        <color rgba="0.866666666666667 0.866666666666667 0.890196078431372 1" />
      </material>
    </visual>
    <collision>
      <origin xyz="0 0 0" rpy="0 0 0" />
      <geometry>
        <mesh filename="./xhand/meshes/right_hand_ring_link2.STL" />
      </geometry>
    </collision>
  </link>
  <joint name="right_hand_ring_joint2" type="revolute">
    <origin xyz="0 0 -0.0558" rpy="0 0 0" />
    <parent link="right_hand_ring_link1" />
    <child link="right_hand_ring_link2" />
    <axis xyz="1 0 0" />
    <limit lower="0" upper="1.92" effort="0.4" velocity="14.38" />
    <dynamics damping="1" friction="1" />
  </joint>
  <link name="right_hand_ring_tip">
    <inertial>
      <origin xyz="-6.93889390390723E-18 6.85042300663241E-15 0" rpy="0 0 0" />
      <mass value="3.53429173528852E-08" />
      <inertia ixx="3.97607820219958E-14" ixy="4.5336858465537E-29" ixz="1.6690203866884E-29" iyy="9.35114688295086E-14" iyz="1.38111976643854E-41" izz="9.35114688295086E-14" />
    </inertial>
    <visual>
      <origin xyz="0 0 0" rpy="0 0 0" />
      <geometry>
        <mesh filename="./xhand/meshes/right_hand_ring_tip.STL" />
      </geometry>
      <material name="">
        <color rgba="0.698039215686274 0.698039215686274 0.698039215686274 1" />
      </material>
    </visual>
    <collision>
      <origin xyz="0 0 0" rpy="0 0 0" />
      <geometry>
        <mesh filename="./xhand/meshes/right_hand_ring_tip.STL" />
      </geometry>
    </collision>
  </link>
  <joint name="right_hand_ring_joint3" type="fixed">
    <origin xyz="0 0 -0.0424999999999994" rpy="0 0 0" />
    <parent link="right_hand_ring_link2" />
    <child link="right_hand_ring_tip" />
    <axis xyz="0 0 0" />
  </joint>
  <link name="right_hand_pinky_link1">
    <inertial>
      <origin xyz="-0.000139769192568043 -0.000800516820207079 -0.035603856454747" rpy="0 0 0" />
      <mass value="0.0630215991316208" />
      <inertia ixx="2.05187455958907E-05" ixy="7.80222924483364E-09" ixz="4.29054564778114E-07" iyy="1.92422608092939E-05" iyz="2.47027716010302E-07" izz="4.15027320974138E-06" />
    </inertial>
    <visual>
      <origin xyz="0 0 0" rpy="0 0 0" />
      <geometry>
        <mesh filename="./xhand/meshes/right_hand_pinky_link1.STL" />
      </geometry>
      <material name="">
        <color rgba="1 1 1 1" />
      </material>
    </visual>
    <collision>
      <origin xyz="0 0 0" rpy="0 0 0" />
      <geometry>
        <mesh filename="./xhand/meshes/right_hand_pinky_link1.STL" />
      </geometry>
    </collision>
  </link>
  <joint name="right_hand_pinky_joint1" type="revolute">
    <origin xyz="-0.036 0.0065 -0.1022" rpy="0 0 0" />
    <parent link="right_hand_link" />
    <child link="right_hand_pinky_link1" />
    <axis xyz="1 0 0" />
    <limit lower="0" upper="1.92" effort="1.1" velocity="8.63" />
    <dynamics damping="1" friction="1" />
  </joint>
  <link name="right_hand_pinky_link2">
    <inertial>
      <origin xyz="-0.000338569414719665 1.93675989681556E-05 -0.0231328539159371" rpy="0 0 0" />
      <mass value="0.0179923076462156" />
      <inertia ixx="3.0181006709957E-06" ixy="-4.92126474056121E-10" ixz="9.0999128816634E-08" iyy="3.01983543495617E-06" iyz="5.99900018674419E-08" izz="9.88538897929235E-07" />
    </inertial>
    <visual>
      <origin xyz="0 0 0" rpy="0 0 0" />
      <geometry>
        <mesh filename="./xhand/meshes/right_hand_pinky_link2.STL" />
      </geometry>
      <material name="">
        <color rgba="0.866666666666667 0.866666666666667 0.890196078431372 1" />
      </material>
    </visual>
    <collision>
      <origin xyz="0 0 0" rpy="0 0 0" />
      <geometry>
        <mesh filename="./xhand/meshes/right_hand_pinky_link2.STL" />
      </geometry>
    </collision>
  </link>
  <joint name="right_hand_pinky_joint2" type="revolute">
    <origin xyz="0 0 -0.0558" rpy="0 0 0" />
    <parent link="right_hand_pinky_link1" />
    <child link="right_hand_pinky_link2" />
    <axis xyz="1 0 0" />
    <limit lower="0" upper="1.92" effort="0.4" velocity="14.38" />
    <dynamics damping="1" friction="1" />
  </joint>
  <link name="right_hand_pinky_tip">
    <inertial>
      <origin xyz="2.08166817117217E-17 9.41000749543619E-15 0" rpy="0 0 0" />
      <mass value="3.53429173528851E-08" />
      <inertia ixx="3.97607820219958E-14" ixy="4.31827422870134E-29" ixz="1.66902038668838E-29" iyy="9.35114688295085E-14" iyz="1.37887768889562E-41" izz="9.35114688295085E-14" />
    </inertial>
    <visual>
      <origin xyz="0 0 0" rpy="0 0 0" />
      <geometry>
        <mesh filename="./xhand/meshes/right_hand_pinky_tip.STL" />
      </geometry>
      <material name="">
        <color rgba="0.698039215686274 0.698039215686274 0.698039215686274 1" />
      </material>
    </visual>
    <collision>
      <origin xyz="0 0 0" rpy="0 0 0" />
      <geometry>
        <mesh filename="./xhand/meshes/right_hand_pinky_tip.STL" />
      </geometry>
    </collision>
  </link>
  <joint name="right_hand_pinky_joint3" type="fixed">
    <origin xyz="0 0 -0.0425" rpy="0 0 0" />
    <parent link="right_hand_pinky_link2" />
    <child link="right_hand_pinky_tip" />
    <axis xyz="0 0 0" />
  </joint> 
</robot>